<?xml version="1.0" encoding="UTF-8"?>
<testng-results skipped="0" failed="1" ignored="0" total="1" passed="0">
  <reporter-output>
  </reporter-output>
  <suite name="Default suite" duration-ms="8475" started-at="2018-09-04T11:33:15Z" finished-at="2018-09-04T11:33:24Z">
    <groups>
    </groups>
    <test name="Default test" duration-ms="8475" started-at="2018-09-04T11:33:15Z" finished-at="2018-09-04T11:33:24Z">
      <class name="testCaseDetails.TC002_LoginFailwithUserneme">
        <test-method status="PASS" signature="startResult()[pri:0, instance:testCaseDetails.TC002_LoginFailwithUserneme@2b2948e2]" name="startResult" is-config="true" duration-ms="433" started-at="2018-09-04T17:03:15Z" finished-at="2018-09-04T17:03:15Z">
          <reporter-output>
          </reporter-output>
        </test-method> <!-- startResult -->
        <test-method status="PASS" signature="setData()[pri:0, instance:testCaseDetails.TC002_LoginFailwithUserneme@2b2948e2]" name="setData" is-config="true" duration-ms="0" started-at="2018-09-04T17:03:15Z" finished-at="2018-09-04T17:03:15Z">
          <reporter-output>
          </reporter-output>
        </test-method> <!-- setData -->
        <test-method status="PASS" signature="startTestCase()[pri:0, instance:testCaseDetails.TC002_LoginFailwithUserneme@2b2948e2]" name="startTestCase" is-config="true" duration-ms="15" started-at="2018-09-04T17:03:15Z" finished-at="2018-09-04T17:03:15Z">
          <reporter-output>
          </reporter-output>
        </test-method> <!-- startTestCase -->
        <test-method status="FAIL" signature="LoginFailwithUserneme()[pri:0, instance:testCaseDetails.TC002_LoginFailwithUserneme@2b2948e2]" name="LoginFailwithUserneme" duration-ms="8403" started-at="2018-09-04T17:03:15Z" finished-at="2018-09-04T17:03:24Z">
          <exception class="java.lang.AssertionError">
            <message>
              <![CDATA[expected [false] but found [Text not found!]]]>
            </message>
            <full-stacktrace>
              <![CDATA[java.lang.AssertionError: expected [false] but found [Text not found!]
	at org.testng.Assert.fail(Assert.java:93)
	at org.testng.Assert.failNotEquals(Assert.java:512)
	at org.testng.Assert.assertEqualsImpl(Assert.java:134)
	at org.testng.Assert.assertEquals(Assert.java:115)
	at org.testng.Assert.assertEquals(Assert.java:178)
	at dmsMethod.CommonMethod.getText(CommonMethod.java:131)
	at testCaseDetails.TC002_LoginFailwithUserneme.LoginFailwithUserneme(TC002_LoginFailwithUserneme.java:23)
	at sun.reflect.NativeMethodAccessorImpl.invoke0(Native Method)
	at sun.reflect.NativeMethodAccessorImpl.invoke(Unknown Source)
	at sun.reflect.DelegatingMethodAccessorImpl.invoke(Unknown Source)
	at java.lang.reflect.Method.invoke(Unknown Source)
	at org.testng.internal.MethodInvocationHelper.invokeMethod(MethodInvocationHelper.java:108)
	at org.testng.internal.Invoker.invokeMethod(Invoker.java:661)
	at org.testng.internal.Invoker.invokeTestMethod(Invoker.java:869)
	at org.testng.internal.Invoker.invokeTestMethods(Invoker.java:1193)
	at org.testng.internal.TestMethodWorker.invokeTestMethods(TestMethodWorker.java:126)
	at org.testng.internal.TestMethodWorker.run(TestMethodWorker.java:109)
	at org.testng.TestRunner.privateRun(TestRunner.java:744)
	at org.testng.TestRunner.run(TestRunner.java:602)
	at org.testng.SuiteRunner.runTest(SuiteRunner.java:380)
	at org.testng.SuiteRunner.runSequentially(SuiteRunner.java:375)
	at org.testng.SuiteRunner.privateRun(SuiteRunner.java:340)
	at org.testng.SuiteRunner.run(SuiteRunner.java:289)
	at org.testng.SuiteRunnerWorker.runSuite(SuiteRunnerWorker.java:52)
	at org.testng.SuiteRunnerWorker.run(SuiteRunnerWorker.java:86)
	at org.testng.TestNG.runSuitesSequentially(TestNG.java:1301)
	at org.testng.TestNG.runSuitesLocally(TestNG.java:1226)
	at org.testng.TestNG.runSuites(TestNG.java:1144)
	at org.testng.TestNG.run(TestNG.java:1115)
	at org.testng.remote.AbstractRemoteTestNG.run(AbstractRemoteTestNG.java:114)
	at org.testng.remote.RemoteTestNG.initAndRun(RemoteTestNG.java:251)
	at org.testng.remote.RemoteTestNG.main(RemoteTestNG.java:77)
]]>
            </full-stacktrace>
          </exception> <!-- java.lang.AssertionError -->
          <reporter-output>
          </reporter-output>
        </test-method> <!-- LoginFailwithUserneme -->
        <test-method status="PASS" signature="stopResult()[pri:0, instance:testCaseDetails.TC002_LoginFailwithUserneme@2b2948e2]" name="stopResult" is-config="true" duration-ms="488" started-at="2018-09-04T17:03:24Z" finished-at="2018-09-04T17:03:24Z">
          <reporter-output>
          </reporter-output>
        </test-method> <!-- stopResult -->
      </class> <!-- testCaseDetails.TC002_LoginFailwithUserneme -->
    </test> <!-- Default test -->
  </suite> <!-- Default suite -->
</testng-results>
